*** Starting uWSGI 2.0.17 (64bit) on [Wed Jul 11 18:19:53 2018] ***
compiled with version: 4.2.1 Compatible Apple LLVM 9.1.0 (clang-902.0.39.2) on 07 July 2018 02:21:17
os: Darwin-17.6.0 Darwin Kernel Version 17.6.0: Tue May  8 15:22:16 PDT 2018; root:xnu-4570.61.1~1/RELEASE_X86_64
nodename: 49-159-54-254.dynamic.elinx.com.tw
machine: x86_64
clock source: unix
pcre jit disabled
detected number of CPU cores: 4
current working directory: /Users/mac/Desktop/Python-Django
writing pidfile to /Users/mac/Desktop/python-django/mysite.pid
detected binary path: /usr/local/bin/uwsgi
chdir() to /Users/mac/Desktop/python-django/mysite
your processes number limit is 709
your memory page size is 4096 bytes
detected max file descriptor number: 8192
lock engine: OSX spinlocks
thunder lock: disabled (you can enable it with --thunder-lock)
uwsgi socket 0 bound to UNIX address /Users/mac/Desktop/python-django/mysite.sock fd 3
Python version: 3.7.0 (default, Jun 29 2018, 20:13:13)  [Clang 9.1.0 (clang-902.0.39.2)]
*** Python threads support is disabled. You can enable it with --enable-threads ***
Python main interpreter initialized at 0x7fd35cd05f60
your server socket listen backlog is limited to 100 connections
your mercy for graceful operations on workers is 60 seconds
mapped 801768 bytes (782 KB) for 10 cores
*** Operational MODE: preforking ***
WSGI app 0 (mountpoint='') ready in 3 seconds on interpreter 0x7fd35cd05f60 pid: 59025 (default app)
*** uWSGI is running in multiple interpreter mode ***
spawned uWSGI master process (pid: 59025)
spawned uWSGI worker 1 (pid: 59090, cores: 1)
spawned uWSGI worker 2 (pid: 59091, cores: 1)
spawned uWSGI worker 3 (pid: 59092, cores: 1)
spawned uWSGI worker 4 (pid: 59093, cores: 1)
spawned uWSGI worker 5 (pid: 59094, cores: 1)
spawned uWSGI worker 6 (pid: 59095, cores: 1)
spawned uWSGI worker 7 (pid: 59096, cores: 1)
spawned uWSGI worker 8 (pid: 59097, cores: 1)
spawned uWSGI worker 9 (pid: 59098, cores: 1)
spawned uWSGI worker 10 (pid: 59099, cores: 1)
Internal Server Error: /
Traceback (most recent call last):
  File "/usr/local/opt/python/Frameworks/Python.framework/Versions/3.7/lib/python3.7/site-packages/django/core/handlers/exception.py", line 35, in inner
    response = get_response(request)
  File "/usr/local/opt/python/Frameworks/Python.framework/Versions/3.7/lib/python3.7/site-packages/django/core/handlers/base.py", line 113, in _get_response
    resolver_match = resolver.resolve(request.path_info)
  File "/usr/local/opt/python/Frameworks/Python.framework/Versions/3.7/lib/python3.7/site-packages/django/urls/resolvers.py", line 498, in resolve
    for pattern in self.url_patterns:
  File "/usr/local/opt/python/Frameworks/Python.framework/Versions/3.7/lib/python3.7/site-packages/django/utils/functional.py", line 36, in __get__
    res = instance.__dict__[self.name] = self.func(instance)
  File "/usr/local/opt/python/Frameworks/Python.framework/Versions/3.7/lib/python3.7/site-packages/django/urls/resolvers.py", line 540, in url_patterns
    patterns = getattr(self.urlconf_module, "urlpatterns", self.urlconf_module)
  File "/usr/local/opt/python/Frameworks/Python.framework/Versions/3.7/lib/python3.7/site-packages/django/utils/functional.py", line 36, in __get__
    res = instance.__dict__[self.name] = self.func(instance)
  File "/usr/local/opt/python/Frameworks/Python.framework/Versions/3.7/lib/python3.7/site-packages/django/urls/resolvers.py", line 533, in urlconf_module
    return import_module(self.urlconf_name)
  File "/usr/local/opt/python/Frameworks/Python.framework/Versions/3.7/lib/python3.7/importlib/__init__.py", line 127, in import_module
    return _bootstrap._gcd_import(name[level:], package, level)
  File "<frozen importlib._bootstrap>", line 1006, in _gcd_import
  File "<frozen importlib._bootstrap>", line 983, in _find_and_load
  File "<frozen importlib._bootstrap>", line 965, in _find_and_load_unlocked
ModuleNotFoundError: No module named 'mysite.urls'
[pid: 59099|app: 0|req: 1/1] 58.182.5.86 () {26 vars in 291 bytes} [Wed Jul 11 11:49:46 2018] GET / => generated 74905 bytes in 270 msecs (HTTP/1.0 500) 4 headers in 129 bytes (12 switches on core 0)
Internal Server Error: /
Traceback (most recent call last):
  File "/usr/local/opt/python/Frameworks/Python.framework/Versions/3.7/lib/python3.7/site-packages/django/core/handlers/exception.py", line 35, in inner
    response = get_response(request)
  File "/usr/local/opt/python/Frameworks/Python.framework/Versions/3.7/lib/python3.7/site-packages/django/core/handlers/base.py", line 113, in _get_response
    resolver_match = resolver.resolve(request.path_info)
  File "/usr/local/opt/python/Frameworks/Python.framework/Versions/3.7/lib/python3.7/site-packages/django/urls/resolvers.py", line 498, in resolve
    for pattern in self.url_patterns:
  File "/usr/local/opt/python/Frameworks/Python.framework/Versions/3.7/lib/python3.7/site-packages/django/utils/functional.py", line 36, in __get__
    res = instance.__dict__[self.name] = self.func(instance)
  File "/usr/local/opt/python/Frameworks/Python.framework/Versions/3.7/lib/python3.7/site-packages/django/urls/resolvers.py", line 540, in url_patterns
    patterns = getattr(self.urlconf_module, "urlpatterns", self.urlconf_module)
  File "/usr/local/opt/python/Frameworks/Python.framework/Versions/3.7/lib/python3.7/site-packages/django/utils/functional.py", line 36, in __get__
    res = instance.__dict__[self.name] = self.func(instance)
  File "/usr/local/opt/python/Frameworks/Python.framework/Versions/3.7/lib/python3.7/site-packages/django/urls/resolvers.py", line 533, in urlconf_module
    return import_module(self.urlconf_name)
  File "/usr/local/opt/python/Frameworks/Python.framework/Versions/3.7/lib/python3.7/importlib/__init__.py", line 127, in import_module
    return _bootstrap._gcd_import(name[level:], package, level)
  File "<frozen importlib._bootstrap>", line 1006, in _gcd_import
  File "<frozen importlib._bootstrap>", line 983, in _find_and_load
  File "<frozen importlib._bootstrap>", line 965, in _find_and_load_unlocked
ModuleNotFoundError: No module named 'mysite.urls'
OSError: write error
[pid: 59099|app: 0|req: 2/2] 116.58.167.60 () {26 vars in 294 bytes} [Wed Jul 11 16:00:29 2018] HEAD / => generated 8063 bytes in 443 msecs (HTTP/1.0 500) 4 headers in 129 bytes (2 switches on core 0)
Internal Server Error: /cache/global/img/gs.gif
Traceback (most recent call last):
  File "/usr/local/opt/python/Frameworks/Python.framework/Versions/3.7/lib/python3.7/site-packages/django/core/handlers/exception.py", line 35, in inner
    response = get_response(request)
  File "/usr/local/opt/python/Frameworks/Python.framework/Versions/3.7/lib/python3.7/site-packages/django/utils/deprecation.py", line 93, in __call__
    response = self.process_request(request)
  File "/usr/local/opt/python/Frameworks/Python.framework/Versions/3.7/lib/python3.7/site-packages/django/middleware/common.py", line 60, in process_request
    if self.should_redirect_with_slash(request):
  File "/usr/local/opt/python/Frameworks/Python.framework/Versions/3.7/lib/python3.7/site-packages/django/middleware/common.py", line 78, in should_redirect_with_slash
    not is_valid_path(request.path_info, urlconf) and
  File "/usr/local/opt/python/Frameworks/Python.framework/Versions/3.7/lib/python3.7/site-packages/django/urls/base.py", line 157, in is_valid_path
    resolve(path, urlconf)
  File "/usr/local/opt/python/Frameworks/Python.framework/Versions/3.7/lib/python3.7/site-packages/django/urls/base.py", line 24, in resolve
    return get_resolver(urlconf).resolve(path)
  File "/usr/local/opt/python/Frameworks/Python.framework/Versions/3.7/lib/python3.7/site-packages/django/urls/resolvers.py", line 498, in resolve
    for pattern in self.url_patterns:
  File "/usr/local/opt/python/Frameworks/Python.framework/Versions/3.7/lib/python3.7/site-packages/django/utils/functional.py", line 36, in __get__
    res = instance.__dict__[self.name] = self.func(instance)
  File "/usr/local/opt/python/Frameworks/Python.framework/Versions/3.7/lib/python3.7/site-packages/django/urls/resolvers.py", line 540, in url_patterns
    patterns = getattr(self.urlconf_module, "urlpatterns", self.urlconf_module)
  File "/usr/local/opt/python/Frameworks/Python.framework/Versions/3.7/lib/python3.7/site-packages/django/utils/functional.py", line 36, in __get__
    res = instance.__dict__[self.name] = self.func(instance)
  File "/usr/local/opt/python/Frameworks/Python.framework/Versions/3.7/lib/python3.7/site-packages/django/urls/resolvers.py", line 533, in urlconf_module
    return import_module(self.urlconf_name)
  File "/usr/local/opt/python/Frameworks/Python.framework/Versions/3.7/lib/python3.7/importlib/__init__.py", line 127, in import_module
    return _bootstrap._gcd_import(name[level:], package, level)
  File "<frozen importlib._bootstrap>", line 1006, in _gcd_import
  File "<frozen importlib._bootstrap>", line 983, in _find_and_load
  File "<frozen importlib._bootstrap>", line 965, in _find_and_load_unlocked
ModuleNotFoundError: No module named 'mysite.urls'
[pid: 59099|app: 0|req: 3/3] 80.82.70.187 () {32 vars in 445 bytes} [Wed Jul 11 17:03:27 2018] GET /cache/global/img/gs.gif => generated 91098 bytes in 408 msecs (HTTP/1.1 500) 1 headers in 63 bytes (14 switches on core 0)
Internal Server Error: /cache/global/img/gs.gif
Traceback (most recent call last):
  File "/usr/local/opt/python/Frameworks/Python.framework/Versions/3.7/lib/python3.7/site-packages/django/core/handlers/exception.py", line 35, in inner
    response = get_response(request)
  File "/usr/local/opt/python/Frameworks/Python.framework/Versions/3.7/lib/python3.7/site-packages/django/utils/deprecation.py", line 93, in __call__
    response = self.process_request(request)
  File "/usr/local/opt/python/Frameworks/Python.framework/Versions/3.7/lib/python3.7/site-packages/django/middleware/common.py", line 60, in process_request
    if self.should_redirect_with_slash(request):
  File "/usr/local/opt/python/Frameworks/Python.framework/Versions/3.7/lib/python3.7/site-packages/django/middleware/common.py", line 78, in should_redirect_with_slash
    not is_valid_path(request.path_info, urlconf) and
  File "/usr/local/opt/python/Frameworks/Python.framework/Versions/3.7/lib/python3.7/site-packages/django/urls/base.py", line 157, in is_valid_path
    resolve(path, urlconf)
  File "/usr/local/opt/python/Frameworks/Python.framework/Versions/3.7/lib/python3.7/site-packages/django/urls/base.py", line 24, in resolve
    return get_resolver(urlconf).resolve(path)
  File "/usr/local/opt/python/Frameworks/Python.framework/Versions/3.7/lib/python3.7/site-packages/django/urls/resolvers.py", line 498, in resolve
    for pattern in self.url_patterns:
  File "/usr/local/opt/python/Frameworks/Python.framework/Versions/3.7/lib/python3.7/site-packages/django/utils/functional.py", line 36, in __get__
    res = instance.__dict__[self.name] = self.func(instance)
  File "/usr/local/opt/python/Frameworks/Python.framework/Versions/3.7/lib/python3.7/site-packages/django/urls/resolvers.py", line 540, in url_patterns
    patterns = getattr(self.urlconf_module, "urlpatterns", self.urlconf_module)
  File "/usr/local/opt/python/Frameworks/Python.framework/Versions/3.7/lib/python3.7/site-packages/django/utils/functional.py", line 36, in __get__
    res = instance.__dict__[self.name] = self.func(instance)
  File "/usr/local/opt/python/Frameworks/Python.framework/Versions/3.7/lib/python3.7/site-packages/django/urls/resolvers.py", line 533, in urlconf_module
    return import_module(self.urlconf_name)
  File "/usr/local/opt/python/Frameworks/Python.framework/Versions/3.7/lib/python3.7/importlib/__init__.py", line 127, in import_module
    return _bootstrap._gcd_import(name[level:], package, level)
  File "<frozen importlib._bootstrap>", line 1006, in _gcd_import
  File "<frozen importlib._bootstrap>", line 983, in _find_and_load
  File "<frozen importlib._bootstrap>", line 965, in _find_and_load_unlocked
ModuleNotFoundError: No module named 'mysite.urls'
[pid: 59099|app: 0|req: 4/4] 80.82.70.187 () {32 vars in 445 bytes} [Thu Jul 12 10:59:39 2018] GET /cache/global/img/gs.gif => generated 91098 bytes in 118 msecs (HTTP/1.1 500) 1 headers in 63 bytes (14 switches on core 0)
Internal Server Error: /
Traceback (most recent call last):
  File "/usr/local/opt/python/Frameworks/Python.framework/Versions/3.7/lib/python3.7/site-packages/django/core/handlers/exception.py", line 35, in inner
    response = get_response(request)
  File "/usr/local/opt/python/Frameworks/Python.framework/Versions/3.7/lib/python3.7/site-packages/django/core/handlers/base.py", line 113, in _get_response
    resolver_match = resolver.resolve(request.path_info)
  File "/usr/local/opt/python/Frameworks/Python.framework/Versions/3.7/lib/python3.7/site-packages/django/urls/resolvers.py", line 498, in resolve
    for pattern in self.url_patterns:
  File "/usr/local/opt/python/Frameworks/Python.framework/Versions/3.7/lib/python3.7/site-packages/django/utils/functional.py", line 36, in __get__
    res = instance.__dict__[self.name] = self.func(instance)
  File "/usr/local/opt/python/Frameworks/Python.framework/Versions/3.7/lib/python3.7/site-packages/django/urls/resolvers.py", line 540, in url_patterns
    patterns = getattr(self.urlconf_module, "urlpatterns", self.urlconf_module)
  File "/usr/local/opt/python/Frameworks/Python.framework/Versions/3.7/lib/python3.7/site-packages/django/utils/functional.py", line 36, in __get__
    res = instance.__dict__[self.name] = self.func(instance)
  File "/usr/local/opt/python/Frameworks/Python.framework/Versions/3.7/lib/python3.7/site-packages/django/urls/resolvers.py", line 533, in urlconf_module
    return import_module(self.urlconf_name)
  File "/usr/local/opt/python/Frameworks/Python.framework/Versions/3.7/lib/python3.7/importlib/__init__.py", line 127, in import_module
    return _bootstrap._gcd_import(name[level:], package, level)
  File "<frozen importlib._bootstrap>", line 1006, in _gcd_import
  File "<frozen importlib._bootstrap>", line 983, in _find_and_load
  File "<frozen importlib._bootstrap>", line 965, in _find_and_load_unlocked
ModuleNotFoundError: No module named 'mysite.urls'
OSError: write error
[pid: 59098|app: 0|req: 1/5] 188.27.17.81 () {26 vars in 293 bytes} [Thu Jul 12 15:41:55 2018] HEAD / => generated 8063 bytes in 390 msecs (HTTP/1.0 500) 4 headers in 129 bytes (3 switches on core 0)
...brutally killing workers...
worker 10 buried after 1 seconds
worker 9 buried after 1 seconds
worker 8 buried after 1 seconds
worker 7 buried after 1 seconds
worker 6 buried after 1 seconds
worker 5 buried after 1 seconds
worker 4 buried after 1 seconds
worker 3 buried after 1 seconds
worker 2 buried after 1 seconds
worker 1 buried after 1 seconds
binary reloading uWSGI...
chdir() to /Users/mac/Desktop/Python-Django
closing all non-uwsgi socket fds > 2 (max_fd = 8192)...
found fd 3 mapped to socket 0 (/Users/mac/Desktop/python-django/mysite.sock)
running /usr/local/bin/uwsgi
[uWSGI] getting INI configuration from uwsgi.ini
*** Starting uWSGI 2.0.17 (64bit) on [Thu Jul 12 23:53:33 2018] ***
compiled with version: 4.2.1 Compatible Apple LLVM 9.1.0 (clang-902.0.39.2) on 07 July 2018 02:21:17
os: Darwin-17.6.0 Darwin Kernel Version 17.6.0: Tue May  8 15:22:16 PDT 2018; root:xnu-4570.61.1~1/RELEASE_X86_64
nodename: 49-159-54-254.dynamic.elinx.com.tw
machine: x86_64
clock source: unix
pcre jit disabled
detected number of CPU cores: 4
current working directory: /Users/mac/Desktop/Python-Django
detected binary path: /usr/local/bin/uwsgi
chdir() to /Users/mac/Desktop/python-django/mysite
your processes number limit is 709
your memory page size is 4096 bytes
detected max file descriptor number: 8192
lock engine: OSX spinlocks
thunder lock: disabled (you can enable it with --thunder-lock)
uwsgi socket 0 inherited UNIX address /Users/mac/Desktop/python-django/mysite.sock fd 3
Python version: 3.7.0 (default, Jun 29 2018, 20:13:13)  [Clang 9.1.0 (clang-902.0.39.2)]
*** Python threads support is disabled. You can enable it with --enable-threads ***
Python main interpreter initialized at 0x7f8600c08910
your server socket listen backlog is limited to 100 connections
your mercy for graceful operations on workers is 60 seconds
mapped 801768 bytes (782 KB) for 10 cores
*** Operational MODE: preforking ***
WSGI app 0 (mountpoint='') ready in 1 seconds on interpreter 0x7f8600c08910 pid: 59025 (default app)
*** uWSGI is running in multiple interpreter mode ***
gracefully (RE)spawned uWSGI master process (pid: 59025)
spawned uWSGI worker 1 (pid: 87294, cores: 1)
spawned uWSGI worker 2 (pid: 87295, cores: 1)
spawned uWSGI worker 3 (pid: 87297, cores: 1)
spawned uWSGI worker 4 (pid: 87299, cores: 1)
spawned uWSGI worker 5 (pid: 87301, cores: 1)
spawned uWSGI worker 6 (pid: 87303, cores: 1)
spawned uWSGI worker 7 (pid: 87305, cores: 1)
spawned uWSGI worker 8 (pid: 87308, cores: 1)
spawned uWSGI worker 9 (pid: 87310, cores: 1)
spawned uWSGI worker 10 (pid: 87312, cores: 1)
